Workbook

Sheet Data Entry
A1: x
A2: x
A3: x | D3: Water Composite 1 | F3: Det Lev | H3: Water Grab 1 -1 | J3: Det Lev | L3: Water Grab 1 - 2 | N3: Det Lev | P3: Water Grab 1 - 3 | R3: Det Lev | T3: Upstream | V3: Det Lev
A4: x
A5: x | B5: Facility Name | D5: Cadillac WWTP | H5: =D5 -> Cadillac WWTP | L5: =D5 -> Cadillac WWTP | P5: =D5 -> Cadillac WWTP | T5: =D5 -> Cadillac WWTP
A6: x | B6: Monitoring Point | D6: 001A | H6: =D6 -> 001A | L6: =D6 -> 001A | P6: =D6 -> 001A | T6: Upstream
A7: x | B7: Survey Period Start Date/time | D7: 43229.431
A8: x | B8: Survey Period End Date/time | D8: 43230.389
A9: x | B9: Flow Rate (MGD) | D9: 1.975
A10: x | B10: Grab Matrix | H10: Wastewater | L10: =H10 -> Wastewater | P10: =H10 -> Wastewater | T10: Surface Water
A11: x | B11: Grab Date Collected | H11: 43229 | L11: 43229 | P11: 43230 | T11: 43229
A12: x | B12: Grab Time Collected | H12: 0.43055556 | L12: 0.64930556 | P12: 0.38888889 | T12: 0.45833333
A13: x
A14: x | B14: Parameters | D14: Results | H14: Results | I14: Units | L14: Results | M14: Units | P14: Results | Q14: Units | T14: Results | U14: Units
A15: x | B15: Temperature (F) | H15: 61 | L15: 59 | P15: 62 | T15: 62
A16: x | B16: pH (S.U.) | H16: 6.99 | L16: 6.8 | P16: 8.17 | T16: 7.06
B17: TRC
A18: x | B18: Dissolved Oxygen | H18: 8.06 | L18: 8.44 | P18: 8.33 | T18: 9.05
B19: Conductivity (umho/cm)
A20: x | B20: Fecal Coliform | H20: --- | I20: (cts/100 ml) | J20: <10 ND | L20: --- | N20: <10 ND | P20: ND | R20: <10 ND | T20: ---
B21: Oil and Grease
A23: x | D23: Results | E23: Units | H23: Results | I23: Units | L23: Results | M23: Units | P23: Results | Q23: Units | T23: Results | U23: Units
A24: x | B24: Suspended Solids | D24: 7 | E24: mg/L | F24: <4 ND
B25: Dissolved Solids | E25: mg/L | F25: <20 ND
A26: x | B26: CBOD-5 | E26: mg/L | F26: <3 ND
B27: BOD-5 | E27: mg/L
B28: COD | E28: mg/L
B29: TOC | E29: mg/L
B30: NO2 | E30: mg/L | F30: <0.01 ND
B31: NO3 + NO2 | E31: mg/L | F31: <0.01 ND
A32: x | B32: NH3 | D32: 0.12 | E32: mg/L | F32: <0.01 ND
B33: Kjeldahl Nitrogen | E33: mg/L | F33: <0.1 ND
A34: x | B34: Total Phosphorus | D34: 0.15 | E34: mg/L | F34: <0.01 ND
B35: Ortho Phosphate | E35: mg/L | F35: <0.01 ND
B36: Total Cyanide | E36: µg/L | F36: <5 ND
B37: Amenable Cyanide | E37: µg/L
A38: x | B38: Available Cyanide | E38: mg/L | F38: <0.002 ND
A39: x | B39: Alkalinity (as CaCO3) | D39: 130 | E39: mg/L | F39: <20 ND | T39: 56
A40: x | B40: Hardness (as CaCO3) | E40: mg/L | F40: <1 ND | T40: 71
B41: Calcium | E41: mg/L | F41: <1 ND
...

Sheet Coverpage
A1: MICHIGAN DEPARTMENT OF ENVIRONMENTAL QUALITY
A2: WATER RESOURCES DIVISION
A3: POINT SOURCE MONITORING
A6: Report of a
A7: Municipal Wastewater Survey
A8: Conducted at
A9: ='Data Entry'!D5 -> Cadillac WWTP
A10: NPDES No. MI0020257
A11: Wexford County
A12: Cadillac, MI 49601
A13: May 9-10, 2018
A16: SURVEY SUMMARY
A18: Wastewater monitoring was performed during one, twenty-four hour survey period starting May 9, 2018 at 10:20 AM.
A20: The results of the physical, chemical and bacteriological analyses are presented in Tables 1 & 2.
A22: The results of this survey are compared to the final limitations in the facility's National Pollutant Discharge Elimination System (NPDES) Permit No. MI in Table 4. | B22: (Hide usually)
A24: The results of this survey are compared to the results reported by the facility in Tables 1 & 2.
A26: A composite sample from monitoring point 001A was split with the facility to compare laboratory analyses. The results are shown in Table 3.
A28: The results of this survey are compared to the results of the previous survey performed in October of 2014 in Table 4.
A30: Samples were preserved according to Table 5. Letter codes for laboratory results are defined in Table 5.
A32: The results of the physical and chemical analyses are presented in Tables 1 & 2. | B32: (Hide)
A34: Table 1 - Analyses of Composite Samples, Table 2 - Analyses of Grab Samples, Table 3 - Organic Compounds, Table 4 - Comparison of the Survey Results with the Facility's Discharge Monitoring Report, Table 5 - Comparison of the Laboratory Analytical Results Obtained by the Facility and the MDEQ Authorized Laboratories, Table 6 - Comparison of Results with Previous Survey, Table 7 - Sample Preservation in this report. | B34: (Hide)

Sheet Survey Procedure
A4: SURVEY PROCEDURE
A6: The flow and samples were obtained as follows:
A8: Sample Location | C8: Flow Measurement | E8: Sampling Methods
A9: 001A - Composite samples collected prior to disinfection from facility compositor | C9: Facility Analysis Report | E9: Grab composite samples
A11: 001A - Grab samples collected post disinfection from outfall to Clam River | C11: --- | E11: Individual grab samples
A13: Upstream samples collected from approximately 20 ft. upstream of outfall to Clam River | C13: --- | E13: Individual grab samples
A18: An automatic sampler composites samples at timed intervals. Samples may be proportional to the instantaneous flow over the weir or through the flume. | F18: (Hid)
A20: A submergible sampler obtains samples at a continuous rate. | F20: (Hid)
A22: A grab composite consists of a series of individual grabs composited into one sample.
A24: An individual grab is a single instantaneous sample.
A26: Samples were analyzed by the MDEQ Laboratory located in Lansing, Michigan, and Merit Laboratories, Inc. in East Lansing, MI.
A28: Samples were preserved according to Table 7. The results of the physical, chemical, and bacteriological analyses are presented in Tables 1 & 2. Letter codes for laboratory results are defined in Table 7. | F28: (Hid)
A30: Samples were preserved according to Table 7. The results of the physical and chemical analyses are presented in Tables 1 & 2. Letter codes for laboratory results are defined in Table 7. | F30: (Hid)
A32: There is no Table 3 in this report. | F32: (Hid)

Sheet Table 1 - Composites
A1: x
A3: x
A4: x | C4: MDEQ Analyses | G4: Cadillac WWTP Analyses
A5: x | B5: Monitoring Point | C5: ='Data Entry'!D6 -> 001A | G5: =C5 -> 001A
A6: x | B6: Survey Period Start Date/Time | C6: ='Data Entry'!D7 -> 43229.431 | G6: 43229.292
A7: x | B7: Survey Period End Date/Time | C7: ='Data Entry'!D8 -> 43230.389 | G7: 43230.292
A8: x | B8: Flow Rate (MGD) | C8: 2.14 | G8: =C8 -> 2.14
A9: x | C9: Results | G9: Results
A10: x | C10: mg/L | E10: lbs/day | G10: mg/L | I10: lbs/day
A11: x | B11: Suspended Solids | C11: =IF('Data Entry'!D24="",'Data Entry'!F24,'Data Entry'!D24) -> 7 | E11: =IF(ISNUMBER(C11),C11*8.34*$C$8,"NA") -> 124.9332 | G11: 4 | I11: =$G$8*8.34*G11 -> 71.3904
B12: Dissolved Solids | C12: =IF('Data Entry'!D25="",'Data Entry'!F25,'Data Entry'!D25) -> <20 ND | E12: =IF(ISNUMBER(C12),C12*8.34*$C$8,"ND Load") -> ND Load | I12: =$G$8*8.34*G12 -> 0
A13: x | B13: CBOD-5 | C13: =IF('Data Entry'!D26="",'Data Entry'!F26,'Data Entry'!D26) -> <3 ND | E13: =IF(ISNUMBER(C13),C13*8.34*$C$8,"NA") -> NA | G13: 9.31 | I13: =$G$8*8.34*G13 -> 166.16116
B14: BOD-5 | C14: =IF('Data Entry'!D27="",'Data Entry'!F27,'Data Entry'!D27) -> 0 | E14: =IF(ISNUMBER(C14),C14*8.34*$C$8,"ND Load") -> 0 | I14: =$G$8*8.34*G14 -> 0
B15: COD | C15: =IF('Data Entry'!D28="",'Data Entry'!F28,'Data Entry'!D28) -> 0 | E15: =IF(ISNUMBER(C15),C15*8.34*$C$8,"ND Load") -> 0 | I15: =$G$8*8.34*G15 -> 0
B16: TOC | C16: =IF('Data Entry'!D29="",'Data Entry'!F29,'Data Entry'!D29) -> 0 | E16: =IF(ISNUMBER(C16),C16*8.34*$C$8,"ND Load") -> 0 | I16: =$G$8*8.34*G16 -> 0
B17: NO2 | C17: =IF('Data Entry'!D30="",'Data Entry'!F30,'Data Entry'!D30) -> <0.01 ND | E17: =IF(ISNUMBER(C17),C17*8.34*$C$8,"ND Load") -> ND Load | I17: =$G$8*8.34*G17 -> 0
B18: NO3 + NO2 | C18: =IF('Data Entry'!D31="",'Data Entry'!F31,'Data Entry'!D31) -> <0.01 ND | E18: =IF(ISNUMBER(C18),C18*8.34*$C$8,"ND Load") -> ND Load | I18: =$G$8*8.34*G18 -> 0
A19: x | B19: NH3 | C19: =IF('Data Entry'!D32="",'Data Entry'!F32,'Data Entry'!D32) -> 0.12 | E19: =IF(ISNUMBER(C19),C19*8.34*$C$8,"NA") -> 2.141712 | G19: 0.556 | I19: =$G$8*8.34*G19 -> 9.9232656
B20: Kjeldahl Nitrogen | C20: =IF('Data Entry'!D33="",'Data Entry'!F33,'Data Entry'!D33) -> <0.1 ND | E20: =IF(ISNUMBER(C20),C20*8.34*$C$8,"ND Load") -> ND Load | I20: =$G$8*8.34*G20 -> 0
A21: x | B21: Total Phosphorus | C21: =IF('Data Entry'!D34="",'Data Entry'!F34,'Data Entry'!D34) -> 0.15 | E21: =IF(ISNUMBER(C21),C21*8.34*$C$8,"NA") -> 2.67714 | G21: 0.111 | I21: =$G$8*8.34*G21 -> 1.9810836
B22: Ortho Phosphate | C22: =IF('Data Entry'!D35="",'Data Entry'!F35,'Data Entry'!D35) -> <0.01 ND | E22: =IF(ISNUMBER(C22),C22*8.34*$C$8,"ND Load") -> ND Load | I22: =$G$8*8.34*G22 -> 0
B23: Total Cyanide | C23: =IF('Data Entry'!D36="",'Data Entry'!F36,'Data Entry'!D36) -> <5 ND | E23: =IF(ISNUMBER(C23),C23*8.34*$C$8,"ND Load") -> ND Load | I23: =$G$8*8.34*G23 -> 0
B24: Amenable Cyanide | C24: =IF('Data Entry'!D37="",'Data Entry'!F37,'Data Entry'!D37) -> 0 | E24: =IF(ISNUMBER(C24),C24*8.34*$C$8,"ND Load") -> 0 | I24: =$G$8*8.34*G24 -> 0
A25: x | B25: Available Cyanide | C25: =IF('Data Entry'!D38="",'Data Entry'!F38,'Data Entry'!D38) -> <0.002 ND | E25: =IF(ISNUMBER(C25),C25*8.34*$C$8,"NA") -> NA | G25: --- | I25: ---
A26: x | B26: Alkalinity (as CaCO3) | C26: =IF('Data Entry'!D39="",'Data Entry'!F39,'Data Entry'!D39) -> 130 | E26: =IF(ISNUMBER(C26),C26*8.34*$C$8,"NA") -> 2320.188 | G26: --- | I26: ---
B27: Conductivity (umho/cm) | C27: =IF('Data Entry'!#REF!="",'Data Entry'!#REF!,'Data Entry'!#REF!) -> #REF! | E27: =IF(ISNUMBER(C27),C27*8.34*$C$8,"ND Load") -> ND Load | I27: =$G$8*8.34*G27 -> 0
B28: Hardness (as CaCO3) | C28: =IF('Data Entry'!D40="",'Data Entry'!F40,'Data Entry'!D40) -> <1 ND | E28: =IF(ISNUMBER(C28),C28*8.34*$C$8,"ND Load") -> ND Load | I28: =$G$8*8.34*G28 -> 0
B29: Calcium | C29: =IF('Data Entry'!D41="",'Data Entry'!F41,'Data Entry'!D41) -> <1 ND | E29: =IF(ISNUMBER(C29),C29*8.34*$C$8,"ND Load") -> ND Load | I29: =$G$8*8.34*G29 -> 0
B30: Sodium | C30: =IF('Data Entry'!D42="",'Data Entry'!F42,'Data Entry'!D42) -> <1 ND | E30: =IF(ISNUMBER(C30),C30*8.34*$C$8,"ND Load") -> ND Load | I30: =$G$8*8.34*G30 -> 0
B31: Potassium | C31: =IF('Data Entry'!D43="",'Data Entry'!F43,'Data Entry'!D43) -> <0.1 ND | E31: =IF(ISNUMBER(C31),C31*8.34*$C$8,"ND Load") -> ND Load | I31: =$G$8*8.34*G31 -> 0
B32: Magnesium | C32: =IF('Data Entry'!D44="",'Data Entry'!F44,'Data Entry'!D44) -> <1 ND | E32: =IF(ISNUMBER(C32),C32*8.34*$C$8,"ND Load") -> ND Load | I32: =$G$8*8.34*G32 -> 0
B33: Chloride | C33: =IF('Data Entry'!D45="",'Data Entry'!F45,'Data Entry'!D45) -> <1 ND | E33: =IF(ISNUMBER(C33),C33*8.34*$C$8,"ND Load") -> ND Load | I33: =$G$8*8.34*G33 -> 0
B34: Sulfate | C34: =IF('Data Entry'!D46="",'Data Entry'!F46,'Data Entry'!D46) -> <2 ND | E34: =IF(ISNUMBER(C34),C34*8.34*$C$8,"ND Load") -> ND Load | I34: =$G$8*8.34*G34 -> 0
B35: Sulfide | C35: =IF('Data Entry'!D47="",'Data Entry'!F47,'Data Entry'!D47) -> 0 | E35: =IF(ISNUMBER(C35),C35*8.34*$C$8,"ND Load") -> 0 | I35: =$G$8*8.34*G35 -> 0
A36: x
A37: x
A38: x | C38: µg/L | E38: lbs/day | G38: µg/L | I38: lbs/day
A39: x | B39: Total Arsenic (As) | C39: =IF('Data Entry'!D49="ND",'Data Entry'!F49,'Data Entry'!D49) -> <1 ND | E39: =IF(ISNUMBER(C39),(C39/1000)*8.34*$C$8,"NA") -> NA | G39: --- | I39: ---
A40: x | B40: Total Barium (Ba) | C40: =IF('Data Entry'!D50="ND",'Data Entry'!F50,'Data Entry'!D50) -> 23 | E40: =IF(ISNUMBER(C40),(C40/1000)*8.34*$C$8,"NA") -> 0.4104948 | G40: --- | I40: ---
A41: x | B41: Total Cadmium (Cd) | C41: =IF('Data Entry'!D51="ND",'Data Entry'!F51,'Data Entry'!D51) -> <0.2 ND | E41: =IF(ISNUMBER(C41),(C41/1000)*8.34*$C$8,"NA") -> NA | G41: --- | I41: ---
...

Sheet Table 2 - Grabs
A3: x
A4: x | D4: MDEQ Analyses | L4: Cadillac WWTP Analyses
A5: x | D5: Grab 1-1 | F5: Grab 1-2 | H5: Grab 1-3 | J5: Upstream | L5: Day 1 | N5: Day 2
A6: x | B6: Monitoring Point | D6: ='Data Entry'!D6 -> 001A | F6: ='Data Entry'!L6 -> 001A | H6: ='Data Entry'!P6 -> 001A | J6: Upstream | L6: =H6 -> 001A | N6: =L6 -> 001A
A7: x | B7: Matrix | D7: ='Data Entry'!H10 -> Wastewater | F7: ='Data Entry'!L10 -> Wastewater | H7: ='Data Entry'!P10 -> Wastewater | J7: Surface Water | L7: Wastewater | N7: Wastewater
A8: x | B8: Date Collected | D8: ='Data Entry'!H11 -> 43229 | F8: ='Data Entry'!L11 -> 43229 | H8: ='Data Entry'!P11 -> 43230 | J8: ='Data Entry'!T11 -> 43229 | L8: =D8 -> 43229 | N8: =H8 -> 43230
A9: x | B9: Time Collected | D9: ='Data Entry'!H12 -> 0.43055556 | F9: ='Data Entry'!L12 -> 0.64930556 | H9: ='Data Entry'!P12 -> 0.38888889 | J9: ='Data Entry'!T12 -> 0.45833333 | L9: 0.29166667 | N9: 0.29166667
A10: x
A11: x | D11: Results | L11: Results
A12: x | B12: Temperature (F) | D12: ='Data Entry'!H15 -> 61 | F12: ='Data Entry'!L15 -> 59 | H12: ='Data Entry'!P15 -> 62 | J12: ='Data Entry'!T15 -> 62 | L12: --- | N12: ---
A13: x | B13: pH (S.U.) | D13: ='Data Entry'!H16 -> 6.99 | F13: ='Data Entry'!L16 -> 6.8 | H13: ='Data Entry'!P16 -> 8.17 | J13: ='Data Entry'!T16 -> 7.06 | L13: 7.08 | N13: 6.94
B14: Total Residual Chlorine | D14: ='Data Entry'!H17 -> 0 | F14: ='Data Entry'!L17 -> 0 | H14: ='Data Entry'!P17 -> 0 | J14: ='Data Entry'!T17 -> 0 | L14: --- | N14: ---
A15: x | B15: Dissolved Oxygen (mg/L) | D15: ='Data Entry'!H18 -> 8.06 | F15: ='Data Entry'!L18 -> 8.44 | H15: ='Data Entry'!P18 -> 8.33 | J15: ='Data Entry'!T18 -> 9.05 | L15: 8.02 | N15: 7.65
B16: Conductivity (umho/cm) | D16: ='Data Entry'!H19 -> 0 | F16: ='Data Entry'!L19 -> 0 | H16: ='Data Entry'!P19 -> 0 | J16: ='Data Entry'!T19 -> 0
A17: x | B17: Fecal Coliform (cts/100 ml) | D17: ='Data Entry'!H20 -> --- | F17: ='Data Entry'!L20 -> --- | H17: =IF(ISNUMBER('Data Entry'!P20),'Data Entry'!P20,'Data Entry'!R20) -> <10 ND | J17: ='Data Entry'!T20 -> --- | L17: 1 | N17: <1 ND
B18: Oil and Grease (grav) | D18: ='Data Entry'!H21 -> 0 | F18: ='Data Entry'!L21 -> 0 | H18: ='Data Entry'!P21 -> 0 | J18: ='Data Entry'!T21 -> 0
B20: *DPD = "No visible indication of TRC using DPD."
D22: mg/L | L22: mg/L
B23: Total Suspended Solids
B24: Dissolved Solids
B25: CBOD-5
B26: BOD-5
B27: COD
B28: TOC
B29: NO2
B30: NO3 + NO2
B31: NH3
B32: Kjeldahl Nitrogen
B33: Total Phosphorus
B34: Ortho Phosphate
... B51: Amenable Cyanide
A52: x | B52: Available Cyanide (mg/L) | D52: --- | F52: --- | H52: <0.002 ND | J52: --- | L52: --- | N52: --- | O52: `
D54: µg/L | L54: µg/L
B55: Phenolics
B56: Total Cadmium (Cd)
B57: Total Chromium (Cr)
B58: Total Copper (Cu)
B59: Total Lead (Pb)
B60: Total Nickel (Ni)
B61: Total Zinc (Zn)
...

Sheet Table 3 - Composite Split
A1: x
A2: x
A4: x | C4: Composite Split
A5: x | B5: Monitoring Point | C5: ='Table 2 - Grabs'!D6 -> 001A
A6: x | B6: Date Collected | C6: ='Data Entry'!P11 -> 43230
A7: x | B7: Time Collected | C7: ='Data Entry'!P12 -> 0.38888889
A8: x
A9: x | C9: MDEQ Results | E9: Facility Results
A10: x | C10: mg/L | E10: mg/L
A11: x | B11: Suspended Solids | C11: 6 | E11: ='Table 1 - Composites'!G11 -> 4
B12: Dissolved Solids
B13: CBOD-5
B14: BOD-5
B15: COD
B16: TOC
B17: NO2
B18: NO3 + NO2
A19: x | B19: NH3 | C19: 0.44 | E19: ='Table 1 - Composites'!G19 -> 0.556
B20: Kjeldahl Nitrogen
A21: x | B21: Total Phosphorus | C21: 0.16 | E21: ='Table 1 - Composites'!G21 -> 0.111
B22: Ortho Phosphate
B23: Total Cyanide
B24: Amenable Cyanide
A25: x | B25: Alkalinity (as CaCO3) | C25: 130 | E25: ='Table 1 - Composites'!G25 -> ---
B26: Conductivity (umho/cm)
B27: Hardness (as CaCO3)
B28: Calcium
B29: Sodium
B30: Potassium
B31: Magnesium
B32: Chloride
B33: Sulfate
B34: Sulfide
B35: Oil and Grease (grav)
B36: Fecal Coliform (cts/100 ml)
A37: x | C37: µg/L | E37: µg/L
A38: x | B38: Total Arsenic (As) | C38: <1 ND | E38: ---
A39: x | B39: Total Barium (Ba) | C39: 24 | E39: ---
A40: x | B40: Total Cadmium (Cd) | C40: <0.2 ND | E40: ---
A41: x | B41: Total Chromium (Cr) | C41: 1.1 | E41: ---
...

Sheet Table 4 - Compare to Old
A1: x
A2: x
A3: x
A4: x | B4: Monitoring Point | C4: ='Data Entry'!D6 -> 001A
A5: x | B5: Matrix | C5: Wastewater
A6: x | B6: Survey Period Start Date/Time | C6: 41926.427 | E6: ='Data Entry'!D7 -> 43229.431
B7: Survey Period End Date/Time | E7: ='Data Entry'!D8 -> 43230.389
A8: x | C8: Results
A9: x | C9: mg/L | E9: mg/L
A10: x | B10: Suspended Solids | C10: 7 | E10: =IF(ISNUMBER('Data Entry'!D24),'Data Entry'!D24,'Data Entry'!F24) -> 7
B11: Dissolved Solids | E11: =IF(ISNUMBER('Data Entry'!D25),'Data Entry'!D25,'Data Entry'!F25) -> <20 ND
A12: x | B12: CBOD-5 | C12: 4.8 | E12: =IF(ISNUMBER('Data Entry'!D26),'Data Entry'!D26,'Data Entry'!F26) -> <3 ND
B13: BOD-5 | E13: =IF(ISNUMBER('Data Entry'!D27),'Data Entry'!D27,'Data Entry'!F27) -> 0
B14: COD | E14: =IF(ISNUMBER('Data Entry'!D28),'Data Entry'!D28,'Data Entry'!F28) -> 0
B15: TOC | E15: =IF(ISNUMBER('Data Entry'!D29),'Data Entry'!D29,'Data Entry'!F29) -> 0
B16: NO2 | E16: =IF(ISNUMBER('Data Entry'!D30),'Data Entry'!D30,'Data Entry'!F30) -> <0.01 ND
B17: NO3 + NO2 | E17: =IF(ISNUMBER('Data Entry'!D31),'Data Entry'!D31,'Data Entry'!F31) -> <0.01 ND
A18: x | B18: NH3 | C18: 0.31 | E18: =IF(ISNUMBER('Data Entry'!D32),'Data Entry'!D32,'Data Entry'!F32) -> 0.12
B19: Kjeldahl Nitrogen | E19: =IF(ISNUMBER('Data Entry'!D33),'Data Entry'!D33,'Data Entry'!F33) -> <0.1 ND
A20: x | B20: Total Phosphorus | C20: 0.15 | E20: =IF(ISNUMBER('Data Entry'!D34),'Data Entry'!D34,'Data Entry'!F34) -> 0.15
B21: Ortho Phosphate | E21: =IF(ISNUMBER('Data Entry'!D35),'Data Entry'!D35,'Data Entry'!F35) -> <0.01 ND
B22: Total Cyanide | E22: =IF(ISNUMBER('Data Entry'!D36),'Data Entry'!D36,'Data Entry'!F36) -> <5 ND
B23: Amenable Cyanide | E23: =IF(ISNUMBER('Data Entry'!D37),'Data Entry'!D37,'Data Entry'!F37) -> 0
A24: x | B24: Available Cyanide | C24: --- | E24: =IF(ISNUMBER('Data Entry'!D38),'Data Entry'!D38,'Data Entry'!F38) -> <0.002 ND
A25: x | B25: Alkalinity (as CaCO3) | C25: 130 | E25: =IF(ISNUMBER('Data Entry'!D39),'Data Entry'!D39,'Data Entry'!F39) -> 130
B26: Hardness (as CaCO3) | E26: =IF(ISNUMBER('Data Entry'!D40),'Data Entry'!D40,'Data Entry'!F40) -> <1 ND
B27: Calcium | E27: =IF(ISNUMBER('Data Entry'!D41),'Data Entry'!D41,'Data Entry'!F41) -> <1 ND
B28: Sodium | E28: =IF(ISNUMBER('Data Entry'!D42),'Data Entry'!D42,'Data Entry'!F42) -> <1 ND
B29: Potassium | E29: =IF(ISNUMBER('Data Entry'!D43),'Data Entry'!D43,'Data Entry'!F43) -> <0.1 ND
B30: Magnesium | E30: =IF(ISNUMBER('Data Entry'!D44),'Data Entry'!D44,'Data Entry'!F44) -> <1 ND
B31: Chloride | E31: =IF(ISNUMBER('Data Entry'!D45),'Data Entry'!D45,'Data Entry'!F45) -> <1 ND
B32: Sulfate | E32: =IF(ISNUMBER('Data Entry'!D46),'Data Entry'!D46,'Data Entry'!F46) -> <2 ND
B33: Sulfide | E33: =IF(ISNUMBER('Data Entry'!D47),'Data Entry'!D47,'Data Entry'!F47) -> 0
A34: x | C34: µg/L | E34: µg/L
A35: x | B35: Total Arsenic (As) | C35: --- | E35: =IF(ISNUMBER('Data Entry'!D49),'Data Entry'!D49,'Data Entry'!F49) -> <1 ND
A36: x | B36: Total Barium (Ba) | C36: --- | E36: =IF(ISNUMBER('Data Entry'!D50),'Data Entry'!D50,'Data Entry'!F50) -> 23
A37: x | B37: Total Cadmium (Cd) | C37: --- | E37: =IF(ISNUMBER('Data Entry'!D51),'Data Entry'!D51,'Data Entry'!F51) -> <0.2 ND
A38: x | B38: Total Chromium (Cr) | C38: --- | E38: =IF(ISNUMBER('Data Entry'!D52),'Data Entry'!D52,'Data Entry'!F52) -> 1.2
A39: x | B39: Total Copper (Cu) | C39: 7.3 | E39: =IF(ISNUMBER('Data Entry'!D53),'Data Entry'!D53,'Data Entry'!F53) -> 6.4
A40: x | B40: Total Lead (Pb) | C40: --- | E40: =IF(ISNUMBER('Data Entry'!D54),'Data Entry'!D54,'Data Entry'!F54) -> <1 ND
...

Sheet Table 5 - Preservatives & Codes
A1: x
A2: x
A3: x
A4: x | B4: Parameter | C4: Preservative
A5: x | B5: ------------------------------------- | C5: -------------------------------------------------------------------------------
A6: x | B6: COD/TOC/Phenol/Nutrients (Chlorine Absent) | C6: 5 drops H2SO4/250 ml (to pH <2)
A7: x
B8: Phenols (Chlorine Present) | C8: Dechlorinate w/ferrous ammonium sulphate (0.141 N) 1 drop/mg/l Cl2/250 ml H2SO4 to pH <2.
B10: Cyanide/Thiocyanates | C10: Dechlorinate if needed with ascorbic acid (0.6 g/l, 10 drops 10 N NaOH (to pH >12)/250 ml.
A12: x | B12: Available Cyanide | C12: Preserved with Sodium Hydroxide to a minimum pH of 12.
A13: x
A14: x | B14: pH & Dissolved Oxygen (D.O.) | C14: Meter reading
A15: x
A16: x | B16: Total Metals | C16: 2 ml 1:1 HNO3/250 ml (to pH <2).
B18: Dissolved Metals (Lab Filtered) | C18: 2 ml 1:1 HNO3/250 ml (to pH <2) after filtration.
A20: x | B20: Microbiology | C20: 2 drops 10% sodium thiosulfate/125 ml to dechlorinate sample
A21: x
B22: Oil & Grease | C22: 10 drops conc. H2SO4/250 ml (to pH <2)
B24: Sulfides | C24: 10 drops 1M ZnAc/250 ml., 1 drop 10 N NaOH to pH 9/250 ml.
B26: Base-neutral & Acid Extractables | C26: Dechlorinate if needed with sodium thiosulfate (1 drop 0.141 N/mg/l Cl2/250 ml).
B28: Purgeable Organics | C28: 5 drops conc. HCl (to pH <2)
A30: x | B30: Samples preserved as required, cooled to 6 degrees Centigrade with chain of custody maintained
A31: x
A32: x
A33: x | B33: Lab Letter Codes
A34: x | B34: -------------------------------------------------------------------------------------------------------------
B35: A - Value reported is mean of two or more determinations.
B37: C - Value calculated from other independent parameters.
B39: D - Analyte value quantified from a dilution(s); reporting limit (RL) raised.
B41: E - Result is estimated due to high recovery of batch QC.
B43: F - Free cyanide was not analyzed due to low level of total cyanide.
B45: G - Result and RL are estimated due to initial calibration standard criteria failure.
B47: H - Sample had exceeded EPA holding time for this analysis when received in the laboratory.
B49: I - Dilution required due to matrix interference;reporting limit (RL) raised.
B51: J - Analyte was positively identified. Value is an estimate.
B53: J - Result was detected between MDL and RL and is considered estimated. (TriMatrix Labs)
B55: K - RL(s) raised due to matrix interferences.
B57: L - Actual value is greater than the value given.
... B113: NC - No confirmation by a second technique.
A115: x | B115: ND - Indicates compound analyzed for but not detected
...
